time 0ms: Simulator started for FCFS [Q <empty>]
time 0ms: Process A arrived and added to ready queue [Q A]
time 0ms: Process B arrived and added to ready queue [Q A B]
time 4ms: Process A started using the CPU [Q B]
time 172ms: Process A completed a CPU burst; 4 bursts to go [Q B]
time 172ms: Process A switching out of CPU; will block on I/O until time 463ms [Q B]
time 180ms: Process B started using the CPU [Q <empty>]
time 190ms: Process C arrived and added to ready queue [Q C]
time 250ms: Process D arrived and added to ready queue [Q C D]
time 463ms: Process A completed I/O; added to ready queue [Q C D A]
time 565ms: Process B terminated [Q C D A]
time 573ms: Process C started using the CPU [Q D A]
time 670ms: Process C completed a CPU burst; 4 bursts to go [Q D A]
time 670ms: Process C switching out of CPU; will block on I/O until time 3173ms [Q D A]
time 678ms: Process D started using the CPU [Q A]
time 2448ms: Process D completed a CPU burst; 1 burst to go [Q A]
time 2448ms: Process D switching out of CPU; will block on I/O until time 3274ms [Q A]
time 2456ms: Process A started using the CPU [Q <empty>]
time 2624ms: Process A completed a CPU burst; 3 bursts to go [Q <empty>]
time 2624ms: Process A switching out of CPU; will block on I/O until time 2915ms [Q <empty>]
time 2915ms: Process A completed I/O; added to ready queue [Q A]
time 2919ms: Process A started using the CPU [Q <empty>]
time 3087ms: Process A completed a CPU burst; 2 bursts to go [Q <empty>]
time 3087ms: Process A switching out of CPU; will block on I/O until time 3378ms [Q <empty>]
time 3173ms: Process C completed I/O; added to ready queue [Q C]
time 3177ms: Process C started using the CPU [Q <empty>]
time 3274ms: Process C completed a CPU burst; 3 bursts to go [Q <empty>]
time 3274ms: Process C switching out of CPU; will block on I/O until time 5777ms [Q <empty>]
time 3274ms: Process D completed I/O; added to ready queue [Q D]
time 3282ms: Process D started using the CPU [Q <empty>]
time 3378ms: Process A completed I/O; added to ready queue [Q A]
time 5052ms: Process D terminated [Q A]
time 5060ms: Process A started using the CPU [Q <empty>]
time 5228ms: Process A completed a CPU burst; 1 burst to go [Q <empty>]
time 5228ms: Process A switching out of CPU; will block on I/O until time 5519ms [Q <empty>]
time 5519ms: Process A completed I/O; added to ready queue [Q A]
time 5523ms: Process A started using the CPU [Q <empty>]
time 5691ms: Process A terminated [Q <empty>]
time 5777ms: Process C completed I/O; added to ready queue [Q C]
time 5781ms: Process C started using the CPU [Q <empty>]
time 5878ms: Process C completed a CPU burst; 2 bursts to go [Q <empty>]
time 5878ms: Process C switching out of CPU; will block on I/O until time 8381ms [Q <empty>]
time 8381ms: Process C completed I/O; added to ready queue [Q C]
time 8385ms: Process C started using the CPU [Q <empty>]
time 8482ms: Process C completed a CPU burst; 1 burst to go [Q <empty>]
time 8482ms: Process C switching out of CPU; will block on I/O until time 10985ms [Q <empty>]
time 10985ms: Process C completed I/O; added to ready queue [Q C]
time 10989ms: Process C started using the CPU [Q <empty>]
time 11086ms: Process C terminated [Q <empty>]
time 11090ms: Simulator ended for FCFS
