time 0ms: Simulator started for FCFS [Q <empty>]
time 0ms: Process A arrived and added to ready queue [Q A]
time 4ms: Process A started using the CPU [Q <empty>]
time 20ms: Process B arrived and added to ready queue [Q B]
time 24ms: Process A completed a CPU burst; 4 bursts to go [Q B]
time 24ms: Process A switching out of CPU; will block on I/O until time 68ms [Q B]
time 32ms: Process B started using the CPU [Q <empty>]
time 68ms: Process B completed a CPU burst; 1 burst to go [Q <empty>]
time 68ms: Process B switching out of CPU; will block on I/O until time 172ms [Q <empty>]
time 68ms: Process A completed I/O; added to ready queue [Q A]
time 68ms: Process C arrived and added to ready queue [Q A C]
time 74ms: Process D arrived and added to ready queue [Q C D]
time 76ms: Process A started using the CPU [Q C D]
time 96ms: Process A completed a CPU burst; 3 bursts to go [Q C D]
time 96ms: Process A switching out of CPU; will block on I/O until time 140ms [Q C D]
time 104ms: Process C started using the CPU [Q D]
time 114ms: Process C terminated [Q D]
time 122ms: Process D started using the CPU [Q <empty>]
time 127ms: Process D terminated [Q <empty>]
time 140ms: Process A completed I/O; added to ready queue [Q A]
time 144ms: Process A started using the CPU [Q <empty>]
time 164ms: Process A completed a CPU burst; 2 bursts to go [Q <empty>]
time 164ms: Process A switching out of CPU; will block on I/O until time 208ms [Q <empty>]
time 172ms: Process B completed I/O; added to ready queue [Q B]
time 176ms: Process B started using the CPU [Q <empty>]
time 208ms: Process A completed I/O; added to ready queue [Q A]
time 212ms: Process B terminated [Q A]
time 220ms: Process A started using the CPU [Q <empty>]
time 240ms: Process A completed a CPU burst; 1 burst to go [Q <empty>]
time 240ms: Process A switching out of CPU; will block on I/O until time 284ms [Q <empty>]
time 284ms: Process A completed I/O; added to ready queue [Q A]
time 288ms: Process A started using the CPU [Q <empty>]
time 308ms: Process A terminated [Q <empty>]
time 312ms: Simulator ended for FCFS

time 0ms: Simulator started for SRT [Q <empty>]
time 0ms: Process A arrived and added to ready queue [Q A]
time 4ms: Process A started using the CPU [Q <empty>]
time 20ms: Process B arrived and added to ready queue [Q B]
time 24ms: Process A completed a CPU burst; 4 bursts to go [Q B]
time 24ms: Process A switching out of CPU; will block on I/O until time 68ms [Q B]
time 32ms: Process B started using the CPU [Q <empty>]
time 68ms: Process B completed a CPU burst; 1 burst to go [Q <empty>]
time 68ms: Process B switching out of CPU; will block on I/O until time 172ms [Q <empty>]
time 68ms: Process A completed I/O; added to ready queue [Q A]
time 68ms: Process C arrived and added to ready queue [Q C A]
time 74ms: Process D arrived and will preempt C [Q A]
time 82ms: Process D started using the CPU [Q C A]
time 87ms: Process D terminated [Q C A]
time 95ms: Process C started using the CPU [Q A]
time 105ms: Process C terminated [Q A]
time 113ms: Process A started using the CPU [Q <empty>]
time 133ms: Process A completed a CPU burst; 3 bursts to go [Q <empty>]
time 133ms: Process A switching out of CPU; will block on I/O until time 177ms [Q <empty>]
time 172ms: Process B completed I/O; added to ready queue [Q B]
time 176ms: Process B started using the CPU [Q <empty>]
time 177ms: Process A completed I/O and will preempt B [Q <empty>]
time 185ms: Process A started using the CPU [Q B]
time 205ms: Process A completed a CPU burst; 2 bursts to go [Q B]
time 205ms: Process A switching out of CPU; will block on I/O until time 249ms [Q B]
time 213ms: Process B started using the CPU with 35ms remaining [Q <empty>]
time 248ms: Process B terminated [Q <empty>]
time 249ms: Process A completed I/O; added to ready queue [Q A]
time 256ms: Process A started using the CPU [Q <empty>]
time 276ms: Process A completed a CPU burst; 1 burst to go [Q <empty>]
time 276ms: Process A switching out of CPU; will block on I/O until time 320ms [Q <empty>]
time 320ms: Process A completed I/O; added to ready queue [Q A]
time 324ms: Process A started using the CPU [Q <empty>]
time 344ms: Process A terminated [Q <empty>]
time 348ms: Simulator ended for SRT

time 0ms: Simulator started for RR [Q <empty>]
time 0ms: Process A arrived and added to ready queue [Q A]
time 4ms: Process A started using the CPU [Q <empty>]
time 20ms: Process B arrived and added to ready queue [Q B]
time 24ms: Process A completed a CPU burst; 4 bursts to go [Q B]
time 24ms: Process A switching out of CPU; will block on I/O until time 68ms [Q B]
time 32ms: Process B started using the CPU [Q <empty>]
time 68ms: Process B completed a CPU burst; 1 burst to go [Q <empty>]
time 68ms: Process B switching out of CPU; will block on I/O until time 172ms [Q <empty>]
time 68ms: Process A completed I/O; added to ready queue [Q A]
time 68ms: Process C arrived and added to ready queue [Q A C]
time 74ms: Process D arrived and added to ready queue [Q C D]
time 76ms: Process A started using the CPU [Q C D]
time 96ms: Process A completed a CPU burst; 3 bursts to go [Q C D]
time 96ms: Process A switching out of CPU; will block on I/O until time 140ms [Q C D]
time 104ms: Process C started using the CPU [Q D]
time 114ms: Process C terminated [Q D]
time 122ms: Process D started using the CPU [Q <empty>]
time 127ms: Process D terminated [Q <empty>]
time 140ms: Process A completed I/O; added to ready queue [Q A]
time 144ms: Process A started using the CPU [Q <empty>]
time 164ms: Process A completed a CPU burst; 2 bursts to go [Q <empty>]
time 164ms: Process A switching out of CPU; will block on I/O until time 208ms [Q <empty>]
time 172ms: Process B completed I/O; added to ready queue [Q B]
time 176ms: Process B started using the CPU [Q <empty>]
time 208ms: Process A completed I/O; added to ready queue [Q A]
time 212ms: Process B terminated [Q A]
time 220ms: Process A started using the CPU [Q <empty>]
time 240ms: Process A completed a CPU burst; 1 burst to go [Q <empty>]
time 240ms: Process A switching out of CPU; will block on I/O until time 284ms [Q <empty>]
time 284ms: Process A completed I/O; added to ready queue [Q A]
time 288ms: Process A started using the CPU [Q <empty>]
time 308ms: Process A terminated [Q <empty>]
time 312ms: Simulator ended for RR
